<?xml version="1.0" ?>
<!-- =================================================================================== -->
<!-- |    This document was autogenerated by xacro from chesstable.urdf.xacro          | -->
<!-- |    EDITING THIS FILE BY HAND IS NOT RECOMMENDED                                 | -->
<!-- =================================================================================== -->
<robot name="chesstable" xmlns:body="http://playerstage.sourceforge.net/gazebo/xmlschema/#body" xmlns:controller="http://playerstage.sourceforge.net/gazebo/xmlschema/#controller" xmlns:gazebo="http://playerstage.sourceforge.net/gazebo/xmlschema/#gz" xmlns:geom="http://playerstage.sourceforge.net/gazebo/xmlschema/#geom" xmlns:interface="http://playerstage.sourceforge.net/gazebo/xmlschema/#interface" xmlns:joint="http://playerstage.sourceforge.net/gazebo/xmlschema/#joint" xmlns:model="http://playerstage.sourceforge.net/gazebo/xmlschema/#model" xmlns:physics="http://playerstage.sourceforge.net/gazebo/xmlschema/#physics" xmlns:renderable="http://playerstage.sourceforge.net/gazebo/xmlschema/#renderable" xmlns:rendering="http://playerstage.sourceforge.net/gazebo/xmlschema/#rendering" xmlns:sensor="http://playerstage.sourceforge.net/gazebo/xmlschema/#sensor" xmlns:xacro="http://ros.org/wiki/xacro" xmlns:xi="http://www.w3.org/2001/XInclude">
  <link name="table_top_link">
    <inertial>
      <mass value="1.0"/>
      <origin xyz="0.52 -0.188 0.375"/>
      <inertia ixx="1" ixy="0" ixz="0" iyy="1" iyz="0" izz="1"/>
    </inertial>
    <visual>
      <origin xyz="0.52 -0.188 0.375"/>
      <geometry>
        <box size="0.5 2.0 0.05"/>
      </geometry>
    </visual>
    <collision>
      <origin xyz="0.52 -0.188 0.375"/>
      <geometry>
        <box size="0.5 2.0 0.05"/>
      </geometry>
    </collision>
  </link>
  <gazebo reference="table_top_link">
    <material>Gazebo/LightWood</material>
    <mu1>50.0</mu1>
    <mu2>50.0</mu2>
    <kp>1000000.0</kp>
    <kd>1.0</kd>
  </gazebo>
  <joint name="leg1_joint" type="fixed">
    <parent link="table_top_link"/>
    <origin rpy="0 0 0" xyz="0.77 0.812 0.4"/>
    <child link="leg1_link"/>
  </joint>
  <link name="leg1_link">
    <inertial>
      <mass value="1.0"/>
      <origin xyz="0 0 -0.2"/>
      <inertia ixx="0.1" ixy="0" ixz="0" iyy="0.1" iyz="0" izz="0.01"/>
    </inertial>
    <visual>
      <origin rpy="0 0 0" xyz="0.0 0.0 -0.2"/>
      <geometry>
        <cylinder length="0.4" radius="0.02"/>
      </geometry>
    </visual>
    <collision>
      <origin rpy="0.0 0.0 0.0" xyz="0.0 0.0 -0.2"/>
      <geometry>
        <cylinder length="0.4" radius="0.02"/>
      </geometry>
    </collision>
  </link>
  <gazebo reference="leg1_link">
    <material>Gazebo/Red</material>
    <mu1>1000.0</mu1>
    <mu2>1000.0</mu2>
    <kp>10000000.0</kp>
    <kd>1.0</kd>
    <selfCollide>true</selfCollide>
  </gazebo>
  <joint name="leg2_joint" type="fixed">
    <parent link="table_top_link"/>
    <origin rpy="0 0 0" xyz="0.27 0.812 0.4"/>
    <child link="leg2_link"/>
  </joint>
  <link name="leg2_link">
    <inertial>
      <mass value="1.0"/>
      <origin xyz="0 0 -0.2"/>
      <inertia ixx="0.1" ixy="0" ixz="0" iyy="0.1" iyz="0" izz="0.01"/>
    </inertial>
    <visual>
      <origin rpy="0 0 0" xyz="0.0 0.0 -0.2"/>
      <geometry>
        <cylinder length="0.4" radius="0.02"/>
      </geometry>
    </visual>
    <collision>
      <origin rpy="0.0 0.0 0.0" xyz="0.0 0.0 -0.2"/>
      <geometry>
        <cylinder length="0.4" radius="0.02"/>
      </geometry>
    </collision>
  </link>
  <gazebo reference="leg2_link">
    <material>Gazebo/Red</material>
    <mu1>1000.0</mu1>
    <mu2>1000.0</mu2>
    <kp>10000000.0</kp>
    <kd>1.0</kd>
    <selfCollide>true</selfCollide>
  </gazebo>
  <joint name="leg3_joint" type="fixed">
    <parent link="table_top_link"/>
    <origin rpy="0 0 0" xyz="0.77 -1.188 0.4"/>
    <child link="leg3_link"/>
  </joint>
  <link name="leg3_link">
    <inertial>
      <mass value="1.0"/>
      <origin xyz="0 0 -0.2"/>
      <inertia ixx="0.1" ixy="0" ixz="0" iyy="0.1" iyz="0" izz="0.01"/>
    </inertial>
    <visual>
      <origin rpy="0 0 0" xyz="0.0 0.0 -0.2"/>
      <geometry>
        <cylinder length="0.4" radius="0.02"/>
      </geometry>
    </visual>
    <collision>
      <origin rpy="0.0 0.0 0.0" xyz="0.0 0.0 -0.2"/>
      <geometry>
        <cylinder length="0.4" radius="0.02"/>
      </geometry>
    </collision>
  </link>
  <gazebo reference="leg3_link">
    <material>Gazebo/Red</material>
    <mu1>1000.0</mu1>
    <mu2>1000.0</mu2>
    <kp>10000000.0</kp>
    <kd>1.0</kd>
    <selfCollide>true</selfCollide>
  </gazebo>
  <joint name="leg4_joint" type="fixed">
    <parent link="table_top_link"/>
    <origin rpy="0 0 0" xyz="0.27 -1.188 0.4"/>
    <child link="leg4_link"/>
  </joint>
  <link name="leg4_link">
    <inertial>
      <mass value="1.0"/>
      <origin xyz="0 0 -0.2"/>
      <inertia ixx="0.1" ixy="0" ixz="0" iyy="0.1" iyz="0" izz="0.01"/>
    </inertial>
    <visual>
      <origin rpy="0 0 0" xyz="0.0 0.0 -0.2"/>
      <geometry>
        <cylinder length="0.4" radius="0.02"/>
      </geometry>
    </visual>
    <collision>
      <origin rpy="0.0 0.0 0.0" xyz="0.0 0.0 -0.2"/>
      <geometry>
        <cylinder length="0.4" radius="0.02"/>
      </geometry>
    </collision>
  </link>
  <gazebo reference="leg4_link">
    <material>Gazebo/Red</material>
    <mu1>1000.0</mu1>
    <mu2>1000.0</mu2>
    <kp>10000000.0</kp>
    <kd>1.0</kd>
    <selfCollide>true</selfCollide>
  </gazebo>
  <gazebo>
    <canonicalBody>table_top_link</canonicalBody>
  </gazebo>
  <!-- The following set of properties were extracted from 
       simulator_gazebo/gazebo_worlds/objects/table.urdf.xacro
    -->
  <!-- 4cm pitch -->
  <!-- MKS units => 10g -->
  <!-- row 1 location -->
  <joint name="blah_center_joint" type="fixed">
    <origin rpy="0 0 0" xyz="0.52 -0.188 0.4"/>
    <parent link="table_top_link"/>
    <child link="blah_center_link"/>
  </joint>
  <link name="blah_center_link">
    <inertial>
      <mass value="4.0"/>
      <origin rpy="0 0 0" xyz="0 0 0.0025"/>
      <inertia ixx="0.00106666666667" ixy="0" ixz="0" iyy="0.00106666666667" iyz="0" izz="0.00106666666667"/>
    </inertial>
    <visual>
      <origin rpy="0 0 0" xyz="0 0 0.0025"/>
      <geometry>
        <box size="0.08 0.08 0.005"/>
      </geometry>
    </visual>
    <collision>
      <origin rpy="0 0 0" xyz="0 0 0.0025"/>
      <geometry>
        <box size="0.08 0.08 0.005"/>
      </geometry>
    </collision>
  </link>
  <gazebo reference="blah_center_link">
    <turnGravityOff>false</turnGravityOff>
    <genTexCoord>true</genTexCoord>
    <kp>100000000.0</kp>
    <kd>1000000.0</kd>
    <material>Gazebo/Black</material>
    <selfCollide>true</selfCollide>
  </gazebo>
  <joint name="blah_a1_joint" type="fixed">
    <origin rpy="0 0 0" xyz="-0.02 0.02 0.0075"/>
    <parent link="blah_center_link"/>
    <child link="blah_a1_link"/>
  </joint>
  <link name="blah_a1_link">
    <inertial>
      <mass value="1"/>
      <inertia ixx="0.000266666666667" ixy="0" ixz="0" iyy="0.000266666666667" iyz="0" izz="0.000266666666667"/>
    </inertial>
    <visual>
      <geometry>
        <box size="0.04 0.04 0.005"/>
      </geometry>
    </visual>
    <collision>
      <geometry>
        <box size="0.04 0.04 0.0025"/>
      </geometry>
    </collision>
  </link>
  <gazebo reference="blah_a1_link">
    <turnGravityOff>false</turnGravityOff>
    <genTexCoord>true</genTexCoord>
    <kp>100000000.0</kp>
    <kd>1000000.0</kd>
    <material>Gazebo/Rocky</material>
    <selfCollide>true</selfCollide>
  </gazebo>
  <joint name="blah_b1_joint" type="fixed">
    <origin rpy="0 0 0" xyz="-0.02 -0.02 0.0075"/>
    <parent link="blah_center_link"/>
    <child link="blah_b1_link"/>
  </joint>
  <link name="blah_b1_link">
    <inertial>
      <mass value="1"/>
      <inertia ixx="0.000266666666667" ixy="0" ixz="0" iyy="0.000266666666667" iyz="0" izz="0.000266666666667"/>
    </inertial>
    <visual>
      <geometry>
        <box size="0.04 0.04 0.005"/>
      </geometry>
    </visual>
    <collision>
      <geometry>
        <box size="0.04 0.04 0.0025"/>
      </geometry>
    </collision>
  </link>
  <gazebo reference="blah_b1_link">
    <turnGravityOff>false</turnGravityOff>
    <genTexCoord>true</genTexCoord>
    <kp>100000000.0</kp>
    <kd>1000000.0</kd>
    <material></material>
    <selfCollide>true</selfCollide>
  </gazebo>
  <joint name="blah_a2_joint" type="fixed">
    <origin rpy="0 0 0" xyz="0.02 0.02 0.0075"/>
    <parent link="blah_center_link"/>
    <child link="blah_a2_link"/>
  </joint>
  <link name="blah_a2_link">
    <inertial>
      <mass value="1"/>
      <inertia ixx="0.000266666666667" ixy="0" ixz="0" iyy="0.000266666666667" iyz="0" izz="0.000266666666667"/>
    </inertial>
    <visual>
      <geometry>
        <box size="0.04 0.04 0.005"/>
      </geometry>
    </visual>
    <collision>
      <geometry>
        <box size="0.04 0.04 0.0025"/>
      </geometry>
    </collision>
  </link>
  <gazebo reference="blah_a2_link">
    <turnGravityOff>false</turnGravityOff>
    <genTexCoord>true</genTexCoord>
    <kp>100000000.0</kp>
    <kd>1000000.0</kd>
    <material></material>
    <selfCollide>true</selfCollide>
  </gazebo>
  <joint name="blah_b2_joint" type="fixed">
    <origin rpy="0 0 0" xyz="0.02 -0.02 0.0075"/>
    <parent link="blah_center_link"/>
    <child link="blah_b2_link"/>
  </joint>
  <link name="blah_b2_link">
    <inertial>
      <mass value="1"/>
      <inertia ixx="0.000266666666667" ixy="0" ixz="0" iyy="0.000266666666667" iyz="0" izz="0.000266666666667"/>
    </inertial>
    <visual>
      <geometry>
        <box size="0.04 0.04 0.005"/>
      </geometry>
    </visual>
    <collision>
      <geometry>
        <box size="0.04 0.04 0.0025"/>
      </geometry>
    </collision>
  </link>
  <gazebo reference="blah_b2_link">
    <turnGravityOff>false</turnGravityOff>
    <genTexCoord>true</genTexCoord>
    <kp>100000000.0</kp>
    <kd>1000000.0</kd>
    <material></material>
    <selfCollide>true</selfCollide>
  </gazebo>
  <!--
  <xacro:chesspiece parent="table_top_link" piecename="wch" color="Black" >
    <origin xyz="${r1} ${ch} ${piece_z}" rpy="0 0 0" />
  </xacro:chesspiece>
-->
  <joint name="wca_base_joint" type="floating">
    <origin rpy="0 0 0" xyz="0.38 -0.048 0.4"/>
    <parent link="table_top_link"/>
    <child link="wca_base"/>
  </joint>
  <link name="wca_base">
    <inertial>
      <mass value="0.00666666666667"/>
      <!-- center of mass (com) is defined w.r.t. link local coordinate system -->
      <origin xyz="0 0 0.00833333333333"/>
      <inertia ixx="2.48070987654e-07" ixy="0" ixz="0" iyy="2.48070987654e-07" iyz="0" izz="1.875e-07"/>
    </inertial>
    <visual>
      <origin rpy="0 0 0" xyz="0 0 0.00833333333333"/>
      <geometry>
        <cylinder length="0.0166666666667" radius="0.0075"/>
      </geometry>
    </visual>
    <collision>
      <origin rpy="0 0 0" xyz="0 0 0.00833333333333"/>
      <geometry>
        <cylinder length="0.0166666666667" radius="0.0075"/>
      </geometry>
    </collision>
  </link>
  <gazebo reference="wca_base">
    <turnGravityOff>false</turnGravityOff>
    <genTexCoord>true</genTexCoord>
    <kp>100000000.0</kp>
    <kd>1000000.0</kd>
    <material>Gazebo/White</material>
    <selfCollide>true</selfCollide>
  </gazebo>
  <joint name="wca_torso_joint" type="fixed">
    <origin rpy="0 0 0" xyz="0 0 0.0166666666667"/>
    <parent link="wca_base"/>
    <child link="wca_torso"/>
  </joint>
  <link name="wca_torso">
    <inertial>
      <mass value="0.00333333333333"/>
      <!-- center of mass (com) is defined w.r.t. link local coordinate system -->
      <origin xyz="0 0 0.0166666666667"/>
      <inertia ixx="3.29475308642e-07" ixy="0" ixz="0" iyy="3.29475308642e-07" iyz="0" izz="4.16666666667e-08"/>
    </inertial>
    <visual>
      <origin rpy="0 0 0" xyz="0 0 0.0166666666667"/>
      <geometry>
        <cylinder length="0.0333333333333" radius="0.005"/>
      </geometry>
    </visual>
    <collision>
      <origin rpy="0 0 0" xyz="0 0 0.0166666666667"/>
      <geometry>
        <cylinder length="0.0333333333333" radius="0.005"/>
      </geometry>
    </collision>
  </link>
  <gazebo reference="wca_torso">
    <turnGravityOff>false</turnGravityOff>
    <genTexCoord>true</genTexCoord>
    <kp>100000000.0</kp>
    <kd>1000000.0</kd>
    <material>Gazebo/White</material>
    <selfCollide>true</selfCollide>
  </gazebo>
  <joint name="wnb_base_joint" type="floating">
    <origin rpy="0 0 0" xyz="0.38 -0.088 0.4"/>
    <parent link="table_top_link"/>
    <child link="wnb_base"/>
  </joint>
  <link name="wnb_base">
    <inertial>
      <mass value="0.00666666666667"/>
      <!-- center of mass (com) is defined w.r.t. link local coordinate system -->
      <origin xyz="0 0 0.00833333333333"/>
      <inertia ixx="2.48070987654e-07" ixy="0" ixz="0" iyy="2.48070987654e-07" iyz="0" izz="1.875e-07"/>
    </inertial>
    <visual>
      <origin rpy="0 0 0" xyz="0 0 0.00833333333333"/>
      <geometry>
        <cylinder length="0.0166666666667" radius="0.0075"/>
      </geometry>
    </visual>
    <collision>
      <origin rpy="0 0 0" xyz="0 0 0.00833333333333"/>
      <geometry>
        <cylinder length="0.0166666666667" radius="0.0075"/>
      </geometry>
    </collision>
  </link>
  <gazebo reference="wnb_base">
    <turnGravityOff>false</turnGravityOff>
    <genTexCoord>true</genTexCoord>
    <kp>100000000.0</kp>
    <kd>1000000.0</kd>
    <material>Gazebo/White</material>
    <selfCollide>true</selfCollide>
  </gazebo>
  <joint name="wnb_torso_joint" type="fixed">
    <origin rpy="0 0 0" xyz="0 0 0.0166666666667"/>
    <parent link="wnb_base"/>
    <child link="wnb_torso"/>
  </joint>
  <link name="wnb_torso">
    <inertial>
      <mass value="0.00333333333333"/>
      <!-- center of mass (com) is defined w.r.t. link local coordinate system -->
      <origin xyz="0 0 0.0166666666667"/>
      <inertia ixx="3.29475308642e-07" ixy="0" ixz="0" iyy="3.29475308642e-07" iyz="0" izz="4.16666666667e-08"/>
    </inertial>
    <visual>
      <origin rpy="0 0 0" xyz="0 0 0.0166666666667"/>
      <geometry>
        <cylinder length="0.0333333333333" radius="0.005"/>
      </geometry>
    </visual>
    <collision>
      <origin rpy="0 0 0" xyz="0 0 0.0166666666667"/>
      <geometry>
        <cylinder length="0.0333333333333" radius="0.005"/>
      </geometry>
    </collision>
  </link>
  <gazebo reference="wnb_torso">
    <turnGravityOff>false</turnGravityOff>
    <genTexCoord>true</genTexCoord>
    <kp>100000000.0</kp>
    <kd>1000000.0</kd>
    <material>Gazebo/White</material>
    <selfCollide>true</selfCollide>
  </gazebo>
  <joint name="wbc_base_joint" type="floating">
    <origin rpy="0 0 0" xyz="0.38 -0.128 0.4"/>
    <parent link="table_top_link"/>
    <child link="wbc_base"/>
  </joint>
  <link name="wbc_base">
    <inertial>
      <mass value="0.00666666666667"/>
      <!-- center of mass (com) is defined w.r.t. link local coordinate system -->
      <origin xyz="0 0 0.00833333333333"/>
      <inertia ixx="2.48070987654e-07" ixy="0" ixz="0" iyy="2.48070987654e-07" iyz="0" izz="1.875e-07"/>
    </inertial>
    <visual>
      <origin rpy="0 0 0" xyz="0 0 0.00833333333333"/>
      <geometry>
        <cylinder length="0.0166666666667" radius="0.0075"/>
      </geometry>
    </visual>
    <collision>
      <origin rpy="0 0 0" xyz="0 0 0.00833333333333"/>
      <geometry>
        <cylinder length="0.0166666666667" radius="0.0075"/>
      </geometry>
    </collision>
  </link>
  <gazebo reference="wbc_base">
    <turnGravityOff>false</turnGravityOff>
    <genTexCoord>true</genTexCoord>
    <kp>100000000.0</kp>
    <kd>1000000.0</kd>
    <material>Gazebo/White</material>
    <selfCollide>true</selfCollide>
  </gazebo>
  <joint name="wbc_torso_joint" type="fixed">
    <origin rpy="0 0 0" xyz="0 0 0.0166666666667"/>
    <parent link="wbc_base"/>
    <child link="wbc_torso"/>
  </joint>
  <link name="wbc_torso">
    <inertial>
      <mass value="0.00333333333333"/>
      <!-- center of mass (com) is defined w.r.t. link local coordinate system -->
      <origin xyz="0 0 0.0166666666667"/>
      <inertia ixx="3.29475308642e-07" ixy="0" ixz="0" iyy="3.29475308642e-07" iyz="0" izz="4.16666666667e-08"/>
    </inertial>
    <visual>
      <origin rpy="0 0 0" xyz="0 0 0.0166666666667"/>
      <geometry>
        <cylinder length="0.0333333333333" radius="0.005"/>
      </geometry>
    </visual>
    <collision>
      <origin rpy="0 0 0" xyz="0 0 0.0166666666667"/>
      <geometry>
        <cylinder length="0.0333333333333" radius="0.005"/>
      </geometry>
    </collision>
  </link>
  <gazebo reference="wbc_torso">
    <turnGravityOff>false</turnGravityOff>
    <genTexCoord>true</genTexCoord>
    <kp>100000000.0</kp>
    <kd>1000000.0</kd>
    <material>Gazebo/White</material>
    <selfCollide>true</selfCollide>
  </gazebo>
  <joint name="wq_base_joint" type="floating">
    <origin rpy="0 0 0" xyz="0.38 -0.168 0.4"/>
    <parent link="table_top_link"/>
    <child link="wq_base"/>
  </joint>
  <link name="wq_base">
    <inertial>
      <mass value="0.00666666666667"/>
      <!-- center of mass (com) is defined w.r.t. link local coordinate system -->
      <origin xyz="0 0 0.00833333333333"/>
      <inertia ixx="2.48070987654e-07" ixy="0" ixz="0" iyy="2.48070987654e-07" iyz="0" izz="1.875e-07"/>
    </inertial>
    <visual>
      <origin rpy="0 0 0" xyz="0 0 0.00833333333333"/>
      <geometry>
        <cylinder length="0.0166666666667" radius="0.0075"/>
      </geometry>
    </visual>
    <collision>
      <origin rpy="0 0 0" xyz="0 0 0.00833333333333"/>
      <geometry>
        <cylinder length="0.0166666666667" radius="0.0075"/>
      </geometry>
    </collision>
  </link>
  <gazebo reference="wq_base">
    <turnGravityOff>false</turnGravityOff>
    <genTexCoord>true</genTexCoord>
    <kp>100000000.0</kp>
    <kd>1000000.0</kd>
    <material>Gazebo/White</material>
    <selfCollide>true</selfCollide>
  </gazebo>
  <joint name="wq_torso_joint" type="fixed">
    <origin rpy="0 0 0" xyz="0 0 0.0166666666667"/>
    <parent link="wq_base"/>
    <child link="wq_torso"/>
  </joint>
  <link name="wq_torso">
    <inertial>
      <mass value="0.00333333333333"/>
      <!-- center of mass (com) is defined w.r.t. link local coordinate system -->
      <origin xyz="0 0 0.0166666666667"/>
      <inertia ixx="3.29475308642e-07" ixy="0" ixz="0" iyy="3.29475308642e-07" iyz="0" izz="4.16666666667e-08"/>
    </inertial>
    <visual>
      <origin rpy="0 0 0" xyz="0 0 0.0166666666667"/>
      <geometry>
        <cylinder length="0.0333333333333" radius="0.005"/>
      </geometry>
    </visual>
    <collision>
      <origin rpy="0 0 0" xyz="0 0 0.0166666666667"/>
      <geometry>
        <cylinder length="0.0333333333333" radius="0.005"/>
      </geometry>
    </collision>
  </link>
  <gazebo reference="wq_torso">
    <turnGravityOff>false</turnGravityOff>
    <genTexCoord>true</genTexCoord>
    <kp>100000000.0</kp>
    <kd>1000000.0</kd>
    <material>Gazebo/White</material>
    <selfCollide>true</selfCollide>
  </gazebo>
  <joint name="wk_base_joint" type="floating">
    <origin rpy="0 0 0" xyz="0.38 -0.208 0.4"/>
    <parent link="table_top_link"/>
    <child link="wk_base"/>
  </joint>
  <link name="wk_base">
    <inertial>
      <mass value="0.00666666666667"/>
      <!-- center of mass (com) is defined w.r.t. link local coordinate system -->
      <origin xyz="0 0 0.00833333333333"/>
      <inertia ixx="2.48070987654e-07" ixy="0" ixz="0" iyy="2.48070987654e-07" iyz="0" izz="1.875e-07"/>
    </inertial>
    <visual>
      <origin rpy="0 0 0" xyz="0 0 0.00833333333333"/>
      <geometry>
        <cylinder length="0.0166666666667" radius="0.0075"/>
      </geometry>
    </visual>
    <collision>
      <origin rpy="0 0 0" xyz="0 0 0.00833333333333"/>
      <geometry>
        <cylinder length="0.0166666666667" radius="0.0075"/>
      </geometry>
    </collision>
  </link>
  <gazebo reference="wk_base">
    <turnGravityOff>false</turnGravityOff>
    <genTexCoord>true</genTexCoord>
    <kp>100000000.0</kp>
    <kd>1000000.0</kd>
    <material>Gazebo/White</material>
    <selfCollide>true</selfCollide>
  </gazebo>
  <joint name="wk_torso_joint" type="fixed">
    <origin rpy="0 0 0" xyz="0 0 0.0166666666667"/>
    <parent link="wk_base"/>
    <child link="wk_torso"/>
  </joint>
  <link name="wk_torso">
    <inertial>
      <mass value="0.00333333333333"/>
      <!-- center of mass (com) is defined w.r.t. link local coordinate system -->
      <origin xyz="0 0 0.0166666666667"/>
      <inertia ixx="3.29475308642e-07" ixy="0" ixz="0" iyy="3.29475308642e-07" iyz="0" izz="4.16666666667e-08"/>
    </inertial>
    <visual>
      <origin rpy="0 0 0" xyz="0 0 0.0166666666667"/>
      <geometry>
        <cylinder length="0.0333333333333" radius="0.005"/>
      </geometry>
    </visual>
    <collision>
      <origin rpy="0 0 0" xyz="0 0 0.0166666666667"/>
      <geometry>
        <cylinder length="0.0333333333333" radius="0.005"/>
      </geometry>
    </collision>
  </link>
  <gazebo reference="wk_torso">
    <turnGravityOff>false</turnGravityOff>
    <genTexCoord>true</genTexCoord>
    <kp>100000000.0</kp>
    <kd>1000000.0</kd>
    <material>Gazebo/White</material>
    <selfCollide>true</selfCollide>
  </gazebo>
  <joint name="wbf_base_joint" type="floating">
    <origin rpy="0 0 0" xyz="0.38 -0.248 0.4"/>
    <parent link="table_top_link"/>
    <child link="wbf_base"/>
  </joint>
  <link name="wbf_base">
    <inertial>
      <mass value="0.00666666666667"/>
      <!-- center of mass (com) is defined w.r.t. link local coordinate system -->
      <origin xyz="0 0 0.00833333333333"/>
      <inertia ixx="2.48070987654e-07" ixy="0" ixz="0" iyy="2.48070987654e-07" iyz="0" izz="1.875e-07"/>
    </inertial>
    <visual>
      <origin rpy="0 0 0" xyz="0 0 0.00833333333333"/>
      <geometry>
        <cylinder length="0.0166666666667" radius="0.0075"/>
      </geometry>
    </visual>
    <collision>
      <origin rpy="0 0 0" xyz="0 0 0.00833333333333"/>
      <geometry>
        <cylinder length="0.0166666666667" radius="0.0075"/>
      </geometry>
    </collision>
  </link>
  <gazebo reference="wbf_base">
    <turnGravityOff>false</turnGravityOff>
    <genTexCoord>true</genTexCoord>
    <kp>100000000.0</kp>
    <kd>1000000.0</kd>
    <material>Gazebo/White</material>
    <selfCollide>true</selfCollide>
  </gazebo>
  <joint name="wbf_torso_joint" type="fixed">
    <origin rpy="0 0 0" xyz="0 0 0.0166666666667"/>
    <parent link="wbf_base"/>
    <child link="wbf_torso"/>
  </joint>
  <link name="wbf_torso">
    <inertial>
      <mass value="0.00333333333333"/>
      <!-- center of mass (com) is defined w.r.t. link local coordinate system -->
      <origin xyz="0 0 0.0166666666667"/>
      <inertia ixx="3.29475308642e-07" ixy="0" ixz="0" iyy="3.29475308642e-07" iyz="0" izz="4.16666666667e-08"/>
    </inertial>
    <visual>
      <origin rpy="0 0 0" xyz="0 0 0.0166666666667"/>
      <geometry>
        <cylinder length="0.0333333333333" radius="0.005"/>
      </geometry>
    </visual>
    <collision>
      <origin rpy="0 0 0" xyz="0 0 0.0166666666667"/>
      <geometry>
        <cylinder length="0.0333333333333" radius="0.005"/>
      </geometry>
    </collision>
  </link>
  <gazebo reference="wbf_torso">
    <turnGravityOff>false</turnGravityOff>
    <genTexCoord>true</genTexCoord>
    <kp>100000000.0</kp>
    <kd>1000000.0</kd>
    <material>Gazebo/White</material>
    <selfCollide>true</selfCollide>
  </gazebo>
  <joint name="wng_base_joint" type="floating">
    <origin rpy="0 0 0" xyz="0.38 -0.288 0.4"/>
    <parent link="table_top_link"/>
    <child link="wng_base"/>
  </joint>
  <link name="wng_base">
    <inertial>
      <mass value="0.00666666666667"/>
      <!-- center of mass (com) is defined w.r.t. link local coordinate system -->
      <origin xyz="0 0 0.00833333333333"/>
      <inertia ixx="2.48070987654e-07" ixy="0" ixz="0" iyy="2.48070987654e-07" iyz="0" izz="1.875e-07"/>
    </inertial>
    <visual>
      <origin rpy="0 0 0" xyz="0 0 0.00833333333333"/>
      <geometry>
        <cylinder length="0.0166666666667" radius="0.0075"/>
      </geometry>
    </visual>
    <collision>
      <origin rpy="0 0 0" xyz="0 0 0.00833333333333"/>
      <geometry>
        <cylinder length="0.0166666666667" radius="0.0075"/>
      </geometry>
    </collision>
  </link>
  <gazebo reference="wng_base">
    <turnGravityOff>false</turnGravityOff>
    <genTexCoord>true</genTexCoord>
    <kp>100000000.0</kp>
    <kd>1000000.0</kd>
    <material>Gazebo/White</material>
    <selfCollide>true</selfCollide>
  </gazebo>
  <joint name="wng_torso_joint" type="fixed">
    <origin rpy="0 0 0" xyz="0 0 0.0166666666667"/>
    <parent link="wng_base"/>
    <child link="wng_torso"/>
  </joint>
  <link name="wng_torso">
    <inertial>
      <mass value="0.00333333333333"/>
      <!-- center of mass (com) is defined w.r.t. link local coordinate system -->
      <origin xyz="0 0 0.0166666666667"/>
      <inertia ixx="3.29475308642e-07" ixy="0" ixz="0" iyy="3.29475308642e-07" iyz="0" izz="4.16666666667e-08"/>
    </inertial>
    <visual>
      <origin rpy="0 0 0" xyz="0 0 0.0166666666667"/>
      <geometry>
        <cylinder length="0.0333333333333" radius="0.005"/>
      </geometry>
    </visual>
    <collision>
      <origin rpy="0 0 0" xyz="0 0 0.0166666666667"/>
      <geometry>
        <cylinder length="0.0333333333333" radius="0.005"/>
      </geometry>
    </collision>
  </link>
  <gazebo reference="wng_torso">
    <turnGravityOff>false</turnGravityOff>
    <genTexCoord>true</genTexCoord>
    <kp>100000000.0</kp>
    <kd>1000000.0</kd>
    <material>Gazebo/White</material>
    <selfCollide>true</selfCollide>
  </gazebo>
  <joint name="wch_base_joint" type="floating">
    <origin rpy="0 0 0" xyz="0.38 -0.328 0.4"/>
    <parent link="table_top_link"/>
    <child link="wch_base"/>
  </joint>
  <link name="wch_base">
    <inertial>
      <mass value="0.00666666666667"/>
      <!-- center of mass (com) is defined w.r.t. link local coordinate system -->
      <origin xyz="0 0 0.00833333333333"/>
      <inertia ixx="2.48070987654e-07" ixy="0" ixz="0" iyy="2.48070987654e-07" iyz="0" izz="1.875e-07"/>
    </inertial>
    <visual>
      <origin rpy="0 0 0" xyz="0 0 0.00833333333333"/>
      <geometry>
        <cylinder length="0.0166666666667" radius="0.0075"/>
      </geometry>
    </visual>
    <collision>
      <origin rpy="0 0 0" xyz="0 0 0.00833333333333"/>
      <geometry>
        <cylinder length="0.0166666666667" radius="0.0075"/>
      </geometry>
    </collision>
  </link>
  <gazebo reference="wch_base">
    <turnGravityOff>false</turnGravityOff>
    <genTexCoord>true</genTexCoord>
    <kp>100000000.0</kp>
    <kd>1000000.0</kd>
    <material>Gazebo/White</material>
    <selfCollide>true</selfCollide>
  </gazebo>
  <joint name="wch_torso_joint" type="fixed">
    <origin rpy="0 0 0" xyz="0 0 0.0166666666667"/>
    <parent link="wch_base"/>
    <child link="wch_torso"/>
  </joint>
  <link name="wch_torso">
    <inertial>
      <mass value="0.00333333333333"/>
      <!-- center of mass (com) is defined w.r.t. link local coordinate system -->
      <origin xyz="0 0 0.0166666666667"/>
      <inertia ixx="3.29475308642e-07" ixy="0" ixz="0" iyy="3.29475308642e-07" iyz="0" izz="4.16666666667e-08"/>
    </inertial>
    <visual>
      <origin rpy="0 0 0" xyz="0 0 0.0166666666667"/>
      <geometry>
        <cylinder length="0.0333333333333" radius="0.005"/>
      </geometry>
    </visual>
    <collision>
      <origin rpy="0 0 0" xyz="0 0 0.0166666666667"/>
      <geometry>
        <cylinder length="0.0333333333333" radius="0.005"/>
      </geometry>
    </collision>
  </link>
  <gazebo reference="wch_torso">
    <turnGravityOff>false</turnGravityOff>
    <genTexCoord>true</genTexCoord>
    <kp>100000000.0</kp>
    <kd>1000000.0</kd>
    <material>Gazebo/White</material>
    <selfCollide>true</selfCollide>
  </gazebo>
  <joint name="wpa_base_joint" type="floating">
    <origin rpy="0 0 0" xyz="0.42 -0.048 0.4"/>
    <parent link="table_top_link"/>
    <child link="wpa_base"/>
  </joint>
  <link name="wpa_base">
    <inertial>
      <mass value="0.00666666666667"/>
      <!-- center of mass (com) is defined w.r.t. link local coordinate system -->
      <origin xyz="0 0 0.00833333333333"/>
      <inertia ixx="2.48070987654e-07" ixy="0" ixz="0" iyy="2.48070987654e-07" iyz="0" izz="1.875e-07"/>
    </inertial>
    <visual>
      <origin rpy="0 0 0" xyz="0 0 0.00833333333333"/>
      <geometry>
        <cylinder length="0.0166666666667" radius="0.0075"/>
      </geometry>
    </visual>
    <collision>
      <origin rpy="0 0 0" xyz="0 0 0.00833333333333"/>
      <geometry>
        <cylinder length="0.0166666666667" radius="0.0075"/>
      </geometry>
    </collision>
  </link>
  <gazebo reference="wpa_base">
    <turnGravityOff>false</turnGravityOff>
    <genTexCoord>true</genTexCoord>
    <kp>100000000.0</kp>
    <kd>1000000.0</kd>
    <material>Gazebo/White</material>
    <selfCollide>true</selfCollide>
  </gazebo>
  <joint name="wpa_torso_joint" type="fixed">
    <origin rpy="0 0 0" xyz="0 0 0.0166666666667"/>
    <parent link="wpa_base"/>
    <child link="wpa_torso"/>
  </joint>
  <link name="wpa_torso">
    <inertial>
      <mass value="0.00333333333333"/>
      <!-- center of mass (com) is defined w.r.t. link local coordinate system -->
      <origin xyz="0 0 0.0166666666667"/>
      <inertia ixx="3.29475308642e-07" ixy="0" ixz="0" iyy="3.29475308642e-07" iyz="0" izz="4.16666666667e-08"/>
    </inertial>
    <visual>
      <origin rpy="0 0 0" xyz="0 0 0.0166666666667"/>
      <geometry>
        <cylinder length="0.0333333333333" radius="0.005"/>
      </geometry>
    </visual>
    <collision>
      <origin rpy="0 0 0" xyz="0 0 0.0166666666667"/>
      <geometry>
        <cylinder length="0.0333333333333" radius="0.005"/>
      </geometry>
    </collision>
  </link>
  <gazebo reference="wpa_torso">
    <turnGravityOff>false</turnGravityOff>
    <genTexCoord>true</genTexCoord>
    <kp>100000000.0</kp>
    <kd>1000000.0</kd>
    <material>Gazebo/White</material>
    <selfCollide>true</selfCollide>
  </gazebo>
  <joint name="wpb_base_joint" type="floating">
    <origin rpy="0 0 0" xyz="0.42 -0.088 0.4"/>
    <parent link="table_top_link"/>
    <child link="wpb_base"/>
  </joint>
  <link name="wpb_base">
    <inertial>
      <mass value="0.00666666666667"/>
      <!-- center of mass (com) is defined w.r.t. link local coordinate system -->
      <origin xyz="0 0 0.00833333333333"/>
      <inertia ixx="2.48070987654e-07" ixy="0" ixz="0" iyy="2.48070987654e-07" iyz="0" izz="1.875e-07"/>
    </inertial>
    <visual>
      <origin rpy="0 0 0" xyz="0 0 0.00833333333333"/>
      <geometry>
        <cylinder length="0.0166666666667" radius="0.0075"/>
      </geometry>
    </visual>
    <collision>
      <origin rpy="0 0 0" xyz="0 0 0.00833333333333"/>
      <geometry>
        <cylinder length="0.0166666666667" radius="0.0075"/>
      </geometry>
    </collision>
  </link>
  <gazebo reference="wpb_base">
    <turnGravityOff>false</turnGravityOff>
    <genTexCoord>true</genTexCoord>
    <kp>100000000.0</kp>
    <kd>1000000.0</kd>
    <material>Gazebo/White</material>
    <selfCollide>true</selfCollide>
  </gazebo>
  <joint name="wpb_torso_joint" type="fixed">
    <origin rpy="0 0 0" xyz="0 0 0.0166666666667"/>
    <parent link="wpb_base"/>
    <child link="wpb_torso"/>
  </joint>
  <link name="wpb_torso">
    <inertial>
      <mass value="0.00333333333333"/>
      <!-- center of mass (com) is defined w.r.t. link local coordinate system -->
      <origin xyz="0 0 0.0166666666667"/>
      <inertia ixx="3.29475308642e-07" ixy="0" ixz="0" iyy="3.29475308642e-07" iyz="0" izz="4.16666666667e-08"/>
    </inertial>
    <visual>
      <origin rpy="0 0 0" xyz="0 0 0.0166666666667"/>
      <geometry>
        <cylinder length="0.0333333333333" radius="0.005"/>
      </geometry>
    </visual>
    <collision>
      <origin rpy="0 0 0" xyz="0 0 0.0166666666667"/>
      <geometry>
        <cylinder length="0.0333333333333" radius="0.005"/>
      </geometry>
    </collision>
  </link>
  <gazebo reference="wpb_torso">
    <turnGravityOff>false</turnGravityOff>
    <genTexCoord>true</genTexCoord>
    <kp>100000000.0</kp>
    <kd>1000000.0</kd>
    <material>Gazebo/White</material>
    <selfCollide>true</selfCollide>
  </gazebo>
  <joint name="wpc_base_joint" type="floating">
    <origin rpy="0 0 0" xyz="0.42 -0.128 0.4"/>
    <parent link="table_top_link"/>
    <child link="wpc_base"/>
  </joint>
  <link name="wpc_base">
    <inertial>
      <mass value="0.00666666666667"/>
      <!-- center of mass (com) is defined w.r.t. link local coordinate system -->
      <origin xyz="0 0 0.00833333333333"/>
      <inertia ixx="2.48070987654e-07" ixy="0" ixz="0" iyy="2.48070987654e-07" iyz="0" izz="1.875e-07"/>
    </inertial>
    <visual>
      <origin rpy="0 0 0" xyz="0 0 0.00833333333333"/>
      <geometry>
        <cylinder length="0.0166666666667" radius="0.0075"/>
      </geometry>
    </visual>
    <collision>
      <origin rpy="0 0 0" xyz="0 0 0.00833333333333"/>
      <geometry>
        <cylinder length="0.0166666666667" radius="0.0075"/>
      </geometry>
    </collision>
  </link>
  <gazebo reference="wpc_base">
    <turnGravityOff>false</turnGravityOff>
    <genTexCoord>true</genTexCoord>
    <kp>100000000.0</kp>
    <kd>1000000.0</kd>
    <material>Gazebo/White</material>
    <selfCollide>true</selfCollide>
  </gazebo>
  <joint name="wpc_torso_joint" type="fixed">
    <origin rpy="0 0 0" xyz="0 0 0.0166666666667"/>
    <parent link="wpc_base"/>
    <child link="wpc_torso"/>
  </joint>
  <link name="wpc_torso">
    <inertial>
      <mass value="0.00333333333333"/>
      <!-- center of mass (com) is defined w.r.t. link local coordinate system -->
      <origin xyz="0 0 0.0166666666667"/>
      <inertia ixx="3.29475308642e-07" ixy="0" ixz="0" iyy="3.29475308642e-07" iyz="0" izz="4.16666666667e-08"/>
    </inertial>
    <visual>
      <origin rpy="0 0 0" xyz="0 0 0.0166666666667"/>
      <geometry>
        <cylinder length="0.0333333333333" radius="0.005"/>
      </geometry>
    </visual>
    <collision>
      <origin rpy="0 0 0" xyz="0 0 0.0166666666667"/>
      <geometry>
        <cylinder length="0.0333333333333" radius="0.005"/>
      </geometry>
    </collision>
  </link>
  <gazebo reference="wpc_torso">
    <turnGravityOff>false</turnGravityOff>
    <genTexCoord>true</genTexCoord>
    <kp>100000000.0</kp>
    <kd>1000000.0</kd>
    <material>Gazebo/White</material>
    <selfCollide>true</selfCollide>
  </gazebo>
  <joint name="wpd_base_joint" type="floating">
    <origin rpy="0 0 0" xyz="0.42 -0.168 0.4"/>
    <parent link="table_top_link"/>
    <child link="wpd_base"/>
  </joint>
  <link name="wpd_base">
    <inertial>
      <mass value="0.00666666666667"/>
      <!-- center of mass (com) is defined w.r.t. link local coordinate system -->
      <origin xyz="0 0 0.00833333333333"/>
      <inertia ixx="2.48070987654e-07" ixy="0" ixz="0" iyy="2.48070987654e-07" iyz="0" izz="1.875e-07"/>
    </inertial>
    <visual>
      <origin rpy="0 0 0" xyz="0 0 0.00833333333333"/>
      <geometry>
        <cylinder length="0.0166666666667" radius="0.0075"/>
      </geometry>
    </visual>
    <collision>
      <origin rpy="0 0 0" xyz="0 0 0.00833333333333"/>
      <geometry>
        <cylinder length="0.0166666666667" radius="0.0075"/>
      </geometry>
    </collision>
  </link>
  <gazebo reference="wpd_base">
    <turnGravityOff>false</turnGravityOff>
    <genTexCoord>true</genTexCoord>
    <kp>100000000.0</kp>
    <kd>1000000.0</kd>
    <material>Gazebo/White</material>
    <selfCollide>true</selfCollide>
  </gazebo>
  <joint name="wpd_torso_joint" type="fixed">
    <origin rpy="0 0 0" xyz="0 0 0.0166666666667"/>
    <parent link="wpd_base"/>
    <child link="wpd_torso"/>
  </joint>
  <link name="wpd_torso">
    <inertial>
      <mass value="0.00333333333333"/>
      <!-- center of mass (com) is defined w.r.t. link local coordinate system -->
      <origin xyz="0 0 0.0166666666667"/>
      <inertia ixx="3.29475308642e-07" ixy="0" ixz="0" iyy="3.29475308642e-07" iyz="0" izz="4.16666666667e-08"/>
    </inertial>
    <visual>
      <origin rpy="0 0 0" xyz="0 0 0.0166666666667"/>
      <geometry>
        <cylinder length="0.0333333333333" radius="0.005"/>
      </geometry>
    </visual>
    <collision>
      <origin rpy="0 0 0" xyz="0 0 0.0166666666667"/>
      <geometry>
        <cylinder length="0.0333333333333" radius="0.005"/>
      </geometry>
    </collision>
  </link>
  <gazebo reference="wpd_torso">
    <turnGravityOff>false</turnGravityOff>
    <genTexCoord>true</genTexCoord>
    <kp>100000000.0</kp>
    <kd>1000000.0</kd>
    <material>Gazebo/White</material>
    <selfCollide>true</selfCollide>
  </gazebo>
  <joint name="wpe_base_joint" type="floating">
    <origin rpy="0 0 0" xyz="0.42 -0.208 0.4"/>
    <parent link="table_top_link"/>
    <child link="wpe_base"/>
  </joint>
  <link name="wpe_base">
    <inertial>
      <mass value="0.00666666666667"/>
      <!-- center of mass (com) is defined w.r.t. link local coordinate system -->
      <origin xyz="0 0 0.00833333333333"/>
      <inertia ixx="2.48070987654e-07" ixy="0" ixz="0" iyy="2.48070987654e-07" iyz="0" izz="1.875e-07"/>
    </inertial>
    <visual>
      <origin rpy="0 0 0" xyz="0 0 0.00833333333333"/>
      <geometry>
        <cylinder length="0.0166666666667" radius="0.0075"/>
      </geometry>
    </visual>
    <collision>
      <origin rpy="0 0 0" xyz="0 0 0.00833333333333"/>
      <geometry>
        <cylinder length="0.0166666666667" radius="0.0075"/>
      </geometry>
    </collision>
  </link>
  <gazebo reference="wpe_base">
    <turnGravityOff>false</turnGravityOff>
    <genTexCoord>true</genTexCoord>
    <kp>100000000.0</kp>
    <kd>1000000.0</kd>
    <material>Gazebo/White</material>
    <selfCollide>true</selfCollide>
  </gazebo>
  <joint name="wpe_torso_joint" type="fixed">
    <origin rpy="0 0 0" xyz="0 0 0.0166666666667"/>
    <parent link="wpe_base"/>
    <child link="wpe_torso"/>
  </joint>
  <link name="wpe_torso">
    <inertial>
      <mass value="0.00333333333333"/>
      <!-- center of mass (com) is defined w.r.t. link local coordinate system -->
      <origin xyz="0 0 0.0166666666667"/>
      <inertia ixx="3.29475308642e-07" ixy="0" ixz="0" iyy="3.29475308642e-07" iyz="0" izz="4.16666666667e-08"/>
    </inertial>
    <visual>
      <origin rpy="0 0 0" xyz="0 0 0.0166666666667"/>
      <geometry>
        <cylinder length="0.0333333333333" radius="0.005"/>
      </geometry>
    </visual>
    <collision>
      <origin rpy="0 0 0" xyz="0 0 0.0166666666667"/>
      <geometry>
        <cylinder length="0.0333333333333" radius="0.005"/>
      </geometry>
    </collision>
  </link>
  <gazebo reference="wpe_torso">
    <turnGravityOff>false</turnGravityOff>
    <genTexCoord>true</genTexCoord>
    <kp>100000000.0</kp>
    <kd>1000000.0</kd>
    <material>Gazebo/White</material>
    <selfCollide>true</selfCollide>
  </gazebo>
  <joint name="wpf_base_joint" type="floating">
    <origin rpy="0 0 0" xyz="0.42 -0.248 0.4"/>
    <parent link="table_top_link"/>
    <child link="wpf_base"/>
  </joint>
  <link name="wpf_base">
    <inertial>
      <mass value="0.00666666666667"/>
      <!-- center of mass (com) is defined w.r.t. link local coordinate system -->
      <origin xyz="0 0 0.00833333333333"/>
      <inertia ixx="2.48070987654e-07" ixy="0" ixz="0" iyy="2.48070987654e-07" iyz="0" izz="1.875e-07"/>
    </inertial>
    <visual>
      <origin rpy="0 0 0" xyz="0 0 0.00833333333333"/>
      <geometry>
        <cylinder length="0.0166666666667" radius="0.0075"/>
      </geometry>
    </visual>
    <collision>
      <origin rpy="0 0 0" xyz="0 0 0.00833333333333"/>
      <geometry>
        <cylinder length="0.0166666666667" radius="0.0075"/>
      </geometry>
    </collision>
  </link>
  <gazebo reference="wpf_base">
    <turnGravityOff>false</turnGravityOff>
    <genTexCoord>true</genTexCoord>
    <kp>100000000.0</kp>
    <kd>1000000.0</kd>
    <material>Gazebo/White</material>
    <selfCollide>true</selfCollide>
  </gazebo>
  <joint name="wpf_torso_joint" type="fixed">
    <origin rpy="0 0 0" xyz="0 0 0.0166666666667"/>
    <parent link="wpf_base"/>
    <child link="wpf_torso"/>
  </joint>
  <link name="wpf_torso">
    <inertial>
      <mass value="0.00333333333333"/>
      <!-- center of mass (com) is defined w.r.t. link local coordinate system -->
      <origin xyz="0 0 0.0166666666667"/>
      <inertia ixx="3.29475308642e-07" ixy="0" ixz="0" iyy="3.29475308642e-07" iyz="0" izz="4.16666666667e-08"/>
    </inertial>
    <visual>
      <origin rpy="0 0 0" xyz="0 0 0.0166666666667"/>
      <geometry>
        <cylinder length="0.0333333333333" radius="0.005"/>
      </geometry>
    </visual>
    <collision>
      <origin rpy="0 0 0" xyz="0 0 0.0166666666667"/>
      <geometry>
        <cylinder length="0.0333333333333" radius="0.005"/>
      </geometry>
    </collision>
  </link>
  <gazebo reference="wpf_torso">
    <turnGravityOff>false</turnGravityOff>
    <genTexCoord>true</genTexCoord>
    <kp>100000000.0</kp>
    <kd>1000000.0</kd>
    <material>Gazebo/White</material>
    <selfCollide>true</selfCollide>
  </gazebo>
  <joint name="wpg_base_joint" type="floating">
    <origin rpy="0 0 0" xyz="0.42 -0.288 0.4"/>
    <parent link="table_top_link"/>
    <child link="wpg_base"/>
  </joint>
  <link name="wpg_base">
    <inertial>
      <mass value="0.00666666666667"/>
      <!-- center of mass (com) is defined w.r.t. link local coordinate system -->
      <origin xyz="0 0 0.00833333333333"/>
      <inertia ixx="2.48070987654e-07" ixy="0" ixz="0" iyy="2.48070987654e-07" iyz="0" izz="1.875e-07"/>
    </inertial>
    <visual>
      <origin rpy="0 0 0" xyz="0 0 0.00833333333333"/>
      <geometry>
        <cylinder length="0.0166666666667" radius="0.0075"/>
      </geometry>
    </visual>
    <collision>
      <origin rpy="0 0 0" xyz="0 0 0.00833333333333"/>
      <geometry>
        <cylinder length="0.0166666666667" radius="0.0075"/>
      </geometry>
    </collision>
  </link>
  <gazebo reference="wpg_base">
    <turnGravityOff>false</turnGravityOff>
    <genTexCoord>true</genTexCoord>
    <kp>100000000.0</kp>
    <kd>1000000.0</kd>
    <material>Gazebo/White</material>
    <selfCollide>true</selfCollide>
  </gazebo>
  <joint name="wpg_torso_joint" type="fixed">
    <origin rpy="0 0 0" xyz="0 0 0.0166666666667"/>
    <parent link="wpg_base"/>
    <child link="wpg_torso"/>
  </joint>
  <link name="wpg_torso">
    <inertial>
      <mass value="0.00333333333333"/>
      <!-- center of mass (com) is defined w.r.t. link local coordinate system -->
      <origin xyz="0 0 0.0166666666667"/>
      <inertia ixx="3.29475308642e-07" ixy="0" ixz="0" iyy="3.29475308642e-07" iyz="0" izz="4.16666666667e-08"/>
    </inertial>
    <visual>
      <origin rpy="0 0 0" xyz="0 0 0.0166666666667"/>
      <geometry>
        <cylinder length="0.0333333333333" radius="0.005"/>
      </geometry>
    </visual>
    <collision>
      <origin rpy="0 0 0" xyz="0 0 0.0166666666667"/>
      <geometry>
        <cylinder length="0.0333333333333" radius="0.005"/>
      </geometry>
    </collision>
  </link>
  <gazebo reference="wpg_torso">
    <turnGravityOff>false</turnGravityOff>
    <genTexCoord>true</genTexCoord>
    <kp>100000000.0</kp>
    <kd>1000000.0</kd>
    <material>Gazebo/White</material>
    <selfCollide>true</selfCollide>
  </gazebo>
  <joint name="wph_base_joint" type="floating">
    <origin rpy="0 0 0" xyz="0.42 -0.328 0.4"/>
    <parent link="table_top_link"/>
    <child link="wph_base"/>
  </joint>
  <link name="wph_base">
    <inertial>
      <mass value="0.00666666666667"/>
      <!-- center of mass (com) is defined w.r.t. link local coordinate system -->
      <origin xyz="0 0 0.00833333333333"/>
      <inertia ixx="2.48070987654e-07" ixy="0" ixz="0" iyy="2.48070987654e-07" iyz="0" izz="1.875e-07"/>
    </inertial>
    <visual>
      <origin rpy="0 0 0" xyz="0 0 0.00833333333333"/>
      <geometry>
        <cylinder length="0.0166666666667" radius="0.0075"/>
      </geometry>
    </visual>
    <collision>
      <origin rpy="0 0 0" xyz="0 0 0.00833333333333"/>
      <geometry>
        <cylinder length="0.0166666666667" radius="0.0075"/>
      </geometry>
    </collision>
  </link>
  <gazebo reference="wph_base">
    <turnGravityOff>false</turnGravityOff>
    <genTexCoord>true</genTexCoord>
    <kp>100000000.0</kp>
    <kd>1000000.0</kd>
    <material>Gazebo/White</material>
    <selfCollide>true</selfCollide>
  </gazebo>
  <joint name="wph_torso_joint" type="fixed">
    <origin rpy="0 0 0" xyz="0 0 0.0166666666667"/>
    <parent link="wph_base"/>
    <child link="wph_torso"/>
  </joint>
  <link name="wph_torso">
    <inertial>
      <mass value="0.00333333333333"/>
      <!-- center of mass (com) is defined w.r.t. link local coordinate system -->
      <origin xyz="0 0 0.0166666666667"/>
      <inertia ixx="3.29475308642e-07" ixy="0" ixz="0" iyy="3.29475308642e-07" iyz="0" izz="4.16666666667e-08"/>
    </inertial>
    <visual>
      <origin rpy="0 0 0" xyz="0 0 0.0166666666667"/>
      <geometry>
        <cylinder length="0.0333333333333" radius="0.005"/>
      </geometry>
    </visual>
    <collision>
      <origin rpy="0 0 0" xyz="0 0 0.0166666666667"/>
      <geometry>
        <cylinder length="0.0333333333333" radius="0.005"/>
      </geometry>
    </collision>
  </link>
  <gazebo reference="wph_torso">
    <turnGravityOff>false</turnGravityOff>
    <genTexCoord>true</genTexCoord>
    <kp>100000000.0</kp>
    <kd>1000000.0</kd>
    <material>Gazebo/White</material>
    <selfCollide>true</selfCollide>
  </gazebo>
  <!-- Set up the black pieces -->
  <joint name="bca_base_joint" type="floating">
    <origin rpy="0 0 0" xyz="0.66 -0.048 0.4"/>
    <parent link="table_top_link"/>
    <child link="bca_base"/>
  </joint>
  <link name="bca_base">
    <inertial>
      <mass value="0.00666666666667"/>
      <!-- center of mass (com) is defined w.r.t. link local coordinate system -->
      <origin xyz="0 0 0.00833333333333"/>
      <inertia ixx="2.48070987654e-07" ixy="0" ixz="0" iyy="2.48070987654e-07" iyz="0" izz="1.875e-07"/>
    </inertial>
    <visual>
      <origin rpy="0 0 0" xyz="0 0 0.00833333333333"/>
      <geometry>
        <cylinder length="0.0166666666667" radius="0.0075"/>
      </geometry>
    </visual>
    <collision>
      <origin rpy="0 0 0" xyz="0 0 0.00833333333333"/>
      <geometry>
        <cylinder length="0.0166666666667" radius="0.0075"/>
      </geometry>
    </collision>
  </link>
  <gazebo reference="bca_base">
    <turnGravityOff>false</turnGravityOff>
    <genTexCoord>true</genTexCoord>
    <kp>100000000.0</kp>
    <kd>1000000.0</kd>
    <material>Gazebo/Black</material>
    <selfCollide>true</selfCollide>
  </gazebo>
  <joint name="bca_torso_joint" type="fixed">
    <origin rpy="0 0 0" xyz="0 0 0.0166666666667"/>
    <parent link="bca_base"/>
    <child link="bca_torso"/>
  </joint>
  <link name="bca_torso">
    <inertial>
      <mass value="0.00333333333333"/>
      <!-- center of mass (com) is defined w.r.t. link local coordinate system -->
      <origin xyz="0 0 0.0166666666667"/>
      <inertia ixx="3.29475308642e-07" ixy="0" ixz="0" iyy="3.29475308642e-07" iyz="0" izz="4.16666666667e-08"/>
    </inertial>
    <visual>
      <origin rpy="0 0 0" xyz="0 0 0.0166666666667"/>
      <geometry>
        <cylinder length="0.0333333333333" radius="0.005"/>
      </geometry>
    </visual>
    <collision>
      <origin rpy="0 0 0" xyz="0 0 0.0166666666667"/>
      <geometry>
        <cylinder length="0.0333333333333" radius="0.005"/>
      </geometry>
    </collision>
  </link>
  <gazebo reference="bca_torso">
    <turnGravityOff>false</turnGravityOff>
    <genTexCoord>true</genTexCoord>
    <kp>100000000.0</kp>
    <kd>1000000.0</kd>
    <material>Gazebo/Black</material>
    <selfCollide>true</selfCollide>
  </gazebo>
  <joint name="bnb_base_joint" type="floating">
    <origin rpy="0 0 0" xyz="0.66 -0.088 0.4"/>
    <parent link="table_top_link"/>
    <child link="bnb_base"/>
  </joint>
  <link name="bnb_base">
    <inertial>
      <mass value="0.00666666666667"/>
      <!-- center of mass (com) is defined w.r.t. link local coordinate system -->
      <origin xyz="0 0 0.00833333333333"/>
      <inertia ixx="2.48070987654e-07" ixy="0" ixz="0" iyy="2.48070987654e-07" iyz="0" izz="1.875e-07"/>
    </inertial>
    <visual>
      <origin rpy="0 0 0" xyz="0 0 0.00833333333333"/>
      <geometry>
        <cylinder length="0.0166666666667" radius="0.0075"/>
      </geometry>
    </visual>
    <collision>
      <origin rpy="0 0 0" xyz="0 0 0.00833333333333"/>
      <geometry>
        <cylinder length="0.0166666666667" radius="0.0075"/>
      </geometry>
    </collision>
  </link>
  <gazebo reference="bnb_base">
    <turnGravityOff>false</turnGravityOff>
    <genTexCoord>true</genTexCoord>
    <kp>100000000.0</kp>
    <kd>1000000.0</kd>
    <material>Gazebo/Black</material>
    <selfCollide>true</selfCollide>
  </gazebo>
  <joint name="bnb_torso_joint" type="fixed">
    <origin rpy="0 0 0" xyz="0 0 0.0166666666667"/>
    <parent link="bnb_base"/>
    <child link="bnb_torso"/>
  </joint>
  <link name="bnb_torso">
    <inertial>
      <mass value="0.00333333333333"/>
      <!-- center of mass (com) is defined w.r.t. link local coordinate system -->
      <origin xyz="0 0 0.0166666666667"/>
      <inertia ixx="3.29475308642e-07" ixy="0" ixz="0" iyy="3.29475308642e-07" iyz="0" izz="4.16666666667e-08"/>
    </inertial>
    <visual>
      <origin rpy="0 0 0" xyz="0 0 0.0166666666667"/>
      <geometry>
        <cylinder length="0.0333333333333" radius="0.005"/>
      </geometry>
    </visual>
    <collision>
      <origin rpy="0 0 0" xyz="0 0 0.0166666666667"/>
      <geometry>
        <cylinder length="0.0333333333333" radius="0.005"/>
      </geometry>
    </collision>
  </link>
  <gazebo reference="bnb_torso">
    <turnGravityOff>false</turnGravityOff>
    <genTexCoord>true</genTexCoord>
    <kp>100000000.0</kp>
    <kd>1000000.0</kd>
    <material>Gazebo/Black</material>
    <selfCollide>true</selfCollide>
  </gazebo>
  <joint name="bbc_base_joint" type="floating">
    <origin rpy="0 0 0" xyz="0.66 -0.128 0.4"/>
    <parent link="table_top_link"/>
    <child link="bbc_base"/>
  </joint>
  <link name="bbc_base">
    <inertial>
      <mass value="0.00666666666667"/>
      <!-- center of mass (com) is defined w.r.t. link local coordinate system -->
      <origin xyz="0 0 0.00833333333333"/>
      <inertia ixx="2.48070987654e-07" ixy="0" ixz="0" iyy="2.48070987654e-07" iyz="0" izz="1.875e-07"/>
    </inertial>
    <visual>
      <origin rpy="0 0 0" xyz="0 0 0.00833333333333"/>
      <geometry>
        <cylinder length="0.0166666666667" radius="0.0075"/>
      </geometry>
    </visual>
    <collision>
      <origin rpy="0 0 0" xyz="0 0 0.00833333333333"/>
      <geometry>
        <cylinder length="0.0166666666667" radius="0.0075"/>
      </geometry>
    </collision>
  </link>
  <gazebo reference="bbc_base">
    <turnGravityOff>false</turnGravityOff>
    <genTexCoord>true</genTexCoord>
    <kp>100000000.0</kp>
    <kd>1000000.0</kd>
    <material>Gazebo/Black</material>
    <selfCollide>true</selfCollide>
  </gazebo>
  <joint name="bbc_torso_joint" type="fixed">
    <origin rpy="0 0 0" xyz="0 0 0.0166666666667"/>
    <parent link="bbc_base"/>
    <child link="bbc_torso"/>
  </joint>
  <link name="bbc_torso">
    <inertial>
      <mass value="0.00333333333333"/>
      <!-- center of mass (com) is defined w.r.t. link local coordinate system -->
      <origin xyz="0 0 0.0166666666667"/>
      <inertia ixx="3.29475308642e-07" ixy="0" ixz="0" iyy="3.29475308642e-07" iyz="0" izz="4.16666666667e-08"/>
    </inertial>
    <visual>
      <origin rpy="0 0 0" xyz="0 0 0.0166666666667"/>
      <geometry>
        <cylinder length="0.0333333333333" radius="0.005"/>
      </geometry>
    </visual>
    <collision>
      <origin rpy="0 0 0" xyz="0 0 0.0166666666667"/>
      <geometry>
        <cylinder length="0.0333333333333" radius="0.005"/>
      </geometry>
    </collision>
  </link>
  <gazebo reference="bbc_torso">
    <turnGravityOff>false</turnGravityOff>
    <genTexCoord>true</genTexCoord>
    <kp>100000000.0</kp>
    <kd>1000000.0</kd>
    <material>Gazebo/Black</material>
    <selfCollide>true</selfCollide>
  </gazebo>
  <joint name="bq_base_joint" type="floating">
    <origin rpy="0 0 0" xyz="0.66 -0.168 0.4"/>
    <parent link="table_top_link"/>
    <child link="bq_base"/>
  </joint>
  <link name="bq_base">
    <inertial>
      <mass value="0.00666666666667"/>
      <!-- center of mass (com) is defined w.r.t. link local coordinate system -->
      <origin xyz="0 0 0.00833333333333"/>
      <inertia ixx="2.48070987654e-07" ixy="0" ixz="0" iyy="2.48070987654e-07" iyz="0" izz="1.875e-07"/>
    </inertial>
    <visual>
      <origin rpy="0 0 0" xyz="0 0 0.00833333333333"/>
      <geometry>
        <cylinder length="0.0166666666667" radius="0.0075"/>
      </geometry>
    </visual>
    <collision>
      <origin rpy="0 0 0" xyz="0 0 0.00833333333333"/>
      <geometry>
        <cylinder length="0.0166666666667" radius="0.0075"/>
      </geometry>
    </collision>
  </link>
  <gazebo reference="bq_base">
    <turnGravityOff>false</turnGravityOff>
    <genTexCoord>true</genTexCoord>
    <kp>100000000.0</kp>
    <kd>1000000.0</kd>
    <material>Gazebo/Black</material>
    <selfCollide>true</selfCollide>
  </gazebo>
  <joint name="bq_torso_joint" type="fixed">
    <origin rpy="0 0 0" xyz="0 0 0.0166666666667"/>
    <parent link="bq_base"/>
    <child link="bq_torso"/>
  </joint>
  <link name="bq_torso">
    <inertial>
      <mass value="0.00333333333333"/>
      <!-- center of mass (com) is defined w.r.t. link local coordinate system -->
      <origin xyz="0 0 0.0166666666667"/>
      <inertia ixx="3.29475308642e-07" ixy="0" ixz="0" iyy="3.29475308642e-07" iyz="0" izz="4.16666666667e-08"/>
    </inertial>
    <visual>
      <origin rpy="0 0 0" xyz="0 0 0.0166666666667"/>
      <geometry>
        <cylinder length="0.0333333333333" radius="0.005"/>
      </geometry>
    </visual>
    <collision>
      <origin rpy="0 0 0" xyz="0 0 0.0166666666667"/>
      <geometry>
        <cylinder length="0.0333333333333" radius="0.005"/>
      </geometry>
    </collision>
  </link>
  <gazebo reference="bq_torso">
    <turnGravityOff>false</turnGravityOff>
    <genTexCoord>true</genTexCoord>
    <kp>100000000.0</kp>
    <kd>1000000.0</kd>
    <material>Gazebo/Black</material>
    <selfCollide>true</selfCollide>
  </gazebo>
  <joint name="bk_base_joint" type="floating">
    <origin rpy="0 0 0" xyz="0.66 -0.208 0.4"/>
    <parent link="table_top_link"/>
    <child link="bk_base"/>
  </joint>
  <link name="bk_base">
    <inertial>
      <mass value="0.00666666666667"/>
      <!-- center of mass (com) is defined w.r.t. link local coordinate system -->
      <origin xyz="0 0 0.00833333333333"/>
      <inertia ixx="2.48070987654e-07" ixy="0" ixz="0" iyy="2.48070987654e-07" iyz="0" izz="1.875e-07"/>
    </inertial>
    <visual>
      <origin rpy="0 0 0" xyz="0 0 0.00833333333333"/>
      <geometry>
        <cylinder length="0.0166666666667" radius="0.0075"/>
      </geometry>
    </visual>
    <collision>
      <origin rpy="0 0 0" xyz="0 0 0.00833333333333"/>
      <geometry>
        <cylinder length="0.0166666666667" radius="0.0075"/>
      </geometry>
    </collision>
  </link>
  <gazebo reference="bk_base">
    <turnGravityOff>false</turnGravityOff>
    <genTexCoord>true</genTexCoord>
    <kp>100000000.0</kp>
    <kd>1000000.0</kd>
    <material>Gazebo/Black</material>
    <selfCollide>true</selfCollide>
  </gazebo>
  <joint name="bk_torso_joint" type="fixed">
    <origin rpy="0 0 0" xyz="0 0 0.0166666666667"/>
    <parent link="bk_base"/>
    <child link="bk_torso"/>
  </joint>
  <link name="bk_torso">
    <inertial>
      <mass value="0.00333333333333"/>
      <!-- center of mass (com) is defined w.r.t. link local coordinate system -->
      <origin xyz="0 0 0.0166666666667"/>
      <inertia ixx="3.29475308642e-07" ixy="0" ixz="0" iyy="3.29475308642e-07" iyz="0" izz="4.16666666667e-08"/>
    </inertial>
    <visual>
      <origin rpy="0 0 0" xyz="0 0 0.0166666666667"/>
      <geometry>
        <cylinder length="0.0333333333333" radius="0.005"/>
      </geometry>
    </visual>
    <collision>
      <origin rpy="0 0 0" xyz="0 0 0.0166666666667"/>
      <geometry>
        <cylinder length="0.0333333333333" radius="0.005"/>
      </geometry>
    </collision>
  </link>
  <gazebo reference="bk_torso">
    <turnGravityOff>false</turnGravityOff>
    <genTexCoord>true</genTexCoord>
    <kp>100000000.0</kp>
    <kd>1000000.0</kd>
    <material>Gazebo/Black</material>
    <selfCollide>true</selfCollide>
  </gazebo>
  <joint name="bbf_base_joint" type="floating">
    <origin rpy="0 0 0" xyz="0.66 -0.248 0.4"/>
    <parent link="table_top_link"/>
    <child link="bbf_base"/>
  </joint>
  <link name="bbf_base">
    <inertial>
      <mass value="0.00666666666667"/>
      <!-- center of mass (com) is defined w.r.t. link local coordinate system -->
      <origin xyz="0 0 0.00833333333333"/>
      <inertia ixx="2.48070987654e-07" ixy="0" ixz="0" iyy="2.48070987654e-07" iyz="0" izz="1.875e-07"/>
    </inertial>
    <visual>
      <origin rpy="0 0 0" xyz="0 0 0.00833333333333"/>
      <geometry>
        <cylinder length="0.0166666666667" radius="0.0075"/>
      </geometry>
    </visual>
    <collision>
      <origin rpy="0 0 0" xyz="0 0 0.00833333333333"/>
      <geometry>
        <cylinder length="0.0166666666667" radius="0.0075"/>
      </geometry>
    </collision>
  </link>
  <gazebo reference="bbf_base">
    <turnGravityOff>false</turnGravityOff>
    <genTexCoord>true</genTexCoord>
    <kp>100000000.0</kp>
    <kd>1000000.0</kd>
    <material>Gazebo/Black</material>
    <selfCollide>true</selfCollide>
  </gazebo>
  <joint name="bbf_torso_joint" type="fixed">
    <origin rpy="0 0 0" xyz="0 0 0.0166666666667"/>
    <parent link="bbf_base"/>
    <child link="bbf_torso"/>
  </joint>
  <link name="bbf_torso">
    <inertial>
      <mass value="0.00333333333333"/>
      <!-- center of mass (com) is defined w.r.t. link local coordinate system -->
      <origin xyz="0 0 0.0166666666667"/>
      <inertia ixx="3.29475308642e-07" ixy="0" ixz="0" iyy="3.29475308642e-07" iyz="0" izz="4.16666666667e-08"/>
    </inertial>
    <visual>
      <origin rpy="0 0 0" xyz="0 0 0.0166666666667"/>
      <geometry>
        <cylinder length="0.0333333333333" radius="0.005"/>
      </geometry>
    </visual>
    <collision>
      <origin rpy="0 0 0" xyz="0 0 0.0166666666667"/>
      <geometry>
        <cylinder length="0.0333333333333" radius="0.005"/>
      </geometry>
    </collision>
  </link>
  <gazebo reference="bbf_torso">
    <turnGravityOff>false</turnGravityOff>
    <genTexCoord>true</genTexCoord>
    <kp>100000000.0</kp>
    <kd>1000000.0</kd>
    <material>Gazebo/Black</material>
    <selfCollide>true</selfCollide>
  </gazebo>
  <joint name="bng_base_joint" type="floating">
    <origin rpy="0 0 0" xyz="0.66 -0.288 0.4"/>
    <parent link="table_top_link"/>
    <child link="bng_base"/>
  </joint>
  <link name="bng_base">
    <inertial>
      <mass value="0.00666666666667"/>
      <!-- center of mass (com) is defined w.r.t. link local coordinate system -->
      <origin xyz="0 0 0.00833333333333"/>
      <inertia ixx="2.48070987654e-07" ixy="0" ixz="0" iyy="2.48070987654e-07" iyz="0" izz="1.875e-07"/>
    </inertial>
    <visual>
      <origin rpy="0 0 0" xyz="0 0 0.00833333333333"/>
      <geometry>
        <cylinder length="0.0166666666667" radius="0.0075"/>
      </geometry>
    </visual>
    <collision>
      <origin rpy="0 0 0" xyz="0 0 0.00833333333333"/>
      <geometry>
        <cylinder length="0.0166666666667" radius="0.0075"/>
      </geometry>
    </collision>
  </link>
  <gazebo reference="bng_base">
    <turnGravityOff>false</turnGravityOff>
    <genTexCoord>true</genTexCoord>
    <kp>100000000.0</kp>
    <kd>1000000.0</kd>
    <material>Gazebo/Black</material>
    <selfCollide>true</selfCollide>
  </gazebo>
  <joint name="bng_torso_joint" type="fixed">
    <origin rpy="0 0 0" xyz="0 0 0.0166666666667"/>
    <parent link="bng_base"/>
    <child link="bng_torso"/>
  </joint>
  <link name="bng_torso">
    <inertial>
      <mass value="0.00333333333333"/>
      <!-- center of mass (com) is defined w.r.t. link local coordinate system -->
      <origin xyz="0 0 0.0166666666667"/>
      <inertia ixx="3.29475308642e-07" ixy="0" ixz="0" iyy="3.29475308642e-07" iyz="0" izz="4.16666666667e-08"/>
    </inertial>
    <visual>
      <origin rpy="0 0 0" xyz="0 0 0.0166666666667"/>
      <geometry>
        <cylinder length="0.0333333333333" radius="0.005"/>
      </geometry>
    </visual>
    <collision>
      <origin rpy="0 0 0" xyz="0 0 0.0166666666667"/>
      <geometry>
        <cylinder length="0.0333333333333" radius="0.005"/>
      </geometry>
    </collision>
  </link>
  <gazebo reference="bng_torso">
    <turnGravityOff>false</turnGravityOff>
    <genTexCoord>true</genTexCoord>
    <kp>100000000.0</kp>
    <kd>1000000.0</kd>
    <material>Gazebo/Black</material>
    <selfCollide>true</selfCollide>
  </gazebo>
  <joint name="bch_base_joint" type="floating">
    <origin rpy="0 0 0" xyz="0.66 -0.328 0.4"/>
    <parent link="table_top_link"/>
    <child link="bch_base"/>
  </joint>
  <link name="bch_base">
    <inertial>
      <mass value="0.00666666666667"/>
      <!-- center of mass (com) is defined w.r.t. link local coordinate system -->
      <origin xyz="0 0 0.00833333333333"/>
      <inertia ixx="2.48070987654e-07" ixy="0" ixz="0" iyy="2.48070987654e-07" iyz="0" izz="1.875e-07"/>
    </inertial>
    <visual>
      <origin rpy="0 0 0" xyz="0 0 0.00833333333333"/>
      <geometry>
        <cylinder length="0.0166666666667" radius="0.0075"/>
      </geometry>
    </visual>
    <collision>
      <origin rpy="0 0 0" xyz="0 0 0.00833333333333"/>
      <geometry>
        <cylinder length="0.0166666666667" radius="0.0075"/>
      </geometry>
    </collision>
  </link>
  <gazebo reference="bch_base">
    <turnGravityOff>false</turnGravityOff>
    <genTexCoord>true</genTexCoord>
    <kp>100000000.0</kp>
    <kd>1000000.0</kd>
    <material>Gazebo/Black</material>
    <selfCollide>true</selfCollide>
  </gazebo>
  <joint name="bch_torso_joint" type="fixed">
    <origin rpy="0 0 0" xyz="0 0 0.0166666666667"/>
    <parent link="bch_base"/>
    <child link="bch_torso"/>
  </joint>
  <link name="bch_torso">
    <inertial>
      <mass value="0.00333333333333"/>
      <!-- center of mass (com) is defined w.r.t. link local coordinate system -->
      <origin xyz="0 0 0.0166666666667"/>
      <inertia ixx="3.29475308642e-07" ixy="0" ixz="0" iyy="3.29475308642e-07" iyz="0" izz="4.16666666667e-08"/>
    </inertial>
    <visual>
      <origin rpy="0 0 0" xyz="0 0 0.0166666666667"/>
      <geometry>
        <cylinder length="0.0333333333333" radius="0.005"/>
      </geometry>
    </visual>
    <collision>
      <origin rpy="0 0 0" xyz="0 0 0.0166666666667"/>
      <geometry>
        <cylinder length="0.0333333333333" radius="0.005"/>
      </geometry>
    </collision>
  </link>
  <gazebo reference="bch_torso">
    <turnGravityOff>false</turnGravityOff>
    <genTexCoord>true</genTexCoord>
    <kp>100000000.0</kp>
    <kd>1000000.0</kd>
    <material>Gazebo/Black</material>
    <selfCollide>true</selfCollide>
  </gazebo>
  <joint name="bpa_base_joint" type="floating">
    <origin rpy="0 0 0" xyz="0.62 -0.048 0.4"/>
    <parent link="table_top_link"/>
    <child link="bpa_base"/>
  </joint>
  <link name="bpa_base">
    <inertial>
      <mass value="0.00666666666667"/>
      <!-- center of mass (com) is defined w.r.t. link local coordinate system -->
      <origin xyz="0 0 0.00833333333333"/>
      <inertia ixx="2.48070987654e-07" ixy="0" ixz="0" iyy="2.48070987654e-07" iyz="0" izz="1.875e-07"/>
    </inertial>
    <visual>
      <origin rpy="0 0 0" xyz="0 0 0.00833333333333"/>
      <geometry>
        <cylinder length="0.0166666666667" radius="0.0075"/>
      </geometry>
    </visual>
    <collision>
      <origin rpy="0 0 0" xyz="0 0 0.00833333333333"/>
      <geometry>
        <cylinder length="0.0166666666667" radius="0.0075"/>
      </geometry>
    </collision>
  </link>
  <gazebo reference="bpa_base">
    <turnGravityOff>false</turnGravityOff>
    <genTexCoord>true</genTexCoord>
    <kp>100000000.0</kp>
    <kd>1000000.0</kd>
    <material>Gazebo/Black</material>
    <selfCollide>true</selfCollide>
  </gazebo>
  <joint name="bpa_torso_joint" type="fixed">
    <origin rpy="0 0 0" xyz="0 0 0.0166666666667"/>
    <parent link="bpa_base"/>
    <child link="bpa_torso"/>
  </joint>
  <link name="bpa_torso">
    <inertial>
      <mass value="0.00333333333333"/>
      <!-- center of mass (com) is defined w.r.t. link local coordinate system -->
      <origin xyz="0 0 0.0166666666667"/>
      <inertia ixx="3.29475308642e-07" ixy="0" ixz="0" iyy="3.29475308642e-07" iyz="0" izz="4.16666666667e-08"/>
    </inertial>
    <visual>
      <origin rpy="0 0 0" xyz="0 0 0.0166666666667"/>
      <geometry>
        <cylinder length="0.0333333333333" radius="0.005"/>
      </geometry>
    </visual>
    <collision>
      <origin rpy="0 0 0" xyz="0 0 0.0166666666667"/>
      <geometry>
        <cylinder length="0.0333333333333" radius="0.005"/>
      </geometry>
    </collision>
  </link>
  <gazebo reference="bpa_torso">
    <turnGravityOff>false</turnGravityOff>
    <genTexCoord>true</genTexCoord>
    <kp>100000000.0</kp>
    <kd>1000000.0</kd>
    <material>Gazebo/Black</material>
    <selfCollide>true</selfCollide>
  </gazebo>
  <joint name="bpb_base_joint" type="floating">
    <origin rpy="0 0 0" xyz="0.62 -0.088 0.4"/>
    <parent link="table_top_link"/>
    <child link="bpb_base"/>
  </joint>
  <link name="bpb_base">
    <inertial>
      <mass value="0.00666666666667"/>
      <!-- center of mass (com) is defined w.r.t. link local coordinate system -->
      <origin xyz="0 0 0.00833333333333"/>
      <inertia ixx="2.48070987654e-07" ixy="0" ixz="0" iyy="2.48070987654e-07" iyz="0" izz="1.875e-07"/>
    </inertial>
    <visual>
      <origin rpy="0 0 0" xyz="0 0 0.00833333333333"/>
      <geometry>
        <cylinder length="0.0166666666667" radius="0.0075"/>
      </geometry>
    </visual>
    <collision>
      <origin rpy="0 0 0" xyz="0 0 0.00833333333333"/>
      <geometry>
        <cylinder length="0.0166666666667" radius="0.0075"/>
      </geometry>
    </collision>
  </link>
  <gazebo reference="bpb_base">
    <turnGravityOff>false</turnGravityOff>
    <genTexCoord>true</genTexCoord>
    <kp>100000000.0</kp>
    <kd>1000000.0</kd>
    <material>Gazebo/Black</material>
    <selfCollide>true</selfCollide>
  </gazebo>
  <joint name="bpb_torso_joint" type="fixed">
    <origin rpy="0 0 0" xyz="0 0 0.0166666666667"/>
    <parent link="bpb_base"/>
    <child link="bpb_torso"/>
  </joint>
  <link name="bpb_torso">
    <inertial>
      <mass value="0.00333333333333"/>
      <!-- center of mass (com) is defined w.r.t. link local coordinate system -->
      <origin xyz="0 0 0.0166666666667"/>
      <inertia ixx="3.29475308642e-07" ixy="0" ixz="0" iyy="3.29475308642e-07" iyz="0" izz="4.16666666667e-08"/>
    </inertial>
    <visual>
      <origin rpy="0 0 0" xyz="0 0 0.0166666666667"/>
      <geometry>
        <cylinder length="0.0333333333333" radius="0.005"/>
      </geometry>
    </visual>
    <collision>
      <origin rpy="0 0 0" xyz="0 0 0.0166666666667"/>
      <geometry>
        <cylinder length="0.0333333333333" radius="0.005"/>
      </geometry>
    </collision>
  </link>
  <gazebo reference="bpb_torso">
    <turnGravityOff>false</turnGravityOff>
    <genTexCoord>true</genTexCoord>
    <kp>100000000.0</kp>
    <kd>1000000.0</kd>
    <material>Gazebo/Black</material>
    <selfCollide>true</selfCollide>
  </gazebo>
  <joint name="bpc_base_joint" type="floating">
    <origin rpy="0 0 0" xyz="0.62 -0.128 0.4"/>
    <parent link="table_top_link"/>
    <child link="bpc_base"/>
  </joint>
  <link name="bpc_base">
    <inertial>
      <mass value="0.00666666666667"/>
      <!-- center of mass (com) is defined w.r.t. link local coordinate system -->
      <origin xyz="0 0 0.00833333333333"/>
      <inertia ixx="2.48070987654e-07" ixy="0" ixz="0" iyy="2.48070987654e-07" iyz="0" izz="1.875e-07"/>
    </inertial>
    <visual>
      <origin rpy="0 0 0" xyz="0 0 0.00833333333333"/>
      <geometry>
        <cylinder length="0.0166666666667" radius="0.0075"/>
      </geometry>
    </visual>
    <collision>
      <origin rpy="0 0 0" xyz="0 0 0.00833333333333"/>
      <geometry>
        <cylinder length="0.0166666666667" radius="0.0075"/>
      </geometry>
    </collision>
  </link>
  <gazebo reference="bpc_base">
    <turnGravityOff>false</turnGravityOff>
    <genTexCoord>true</genTexCoord>
    <kp>100000000.0</kp>
    <kd>1000000.0</kd>
    <material>Gazebo/Black</material>
    <selfCollide>true</selfCollide>
  </gazebo>
  <joint name="bpc_torso_joint" type="fixed">
    <origin rpy="0 0 0" xyz="0 0 0.0166666666667"/>
    <parent link="bpc_base"/>
    <child link="bpc_torso"/>
  </joint>
  <link name="bpc_torso">
    <inertial>
      <mass value="0.00333333333333"/>
      <!-- center of mass (com) is defined w.r.t. link local coordinate system -->
      <origin xyz="0 0 0.0166666666667"/>
      <inertia ixx="3.29475308642e-07" ixy="0" ixz="0" iyy="3.29475308642e-07" iyz="0" izz="4.16666666667e-08"/>
    </inertial>
    <visual>
      <origin rpy="0 0 0" xyz="0 0 0.0166666666667"/>
      <geometry>
        <cylinder length="0.0333333333333" radius="0.005"/>
      </geometry>
    </visual>
    <collision>
      <origin rpy="0 0 0" xyz="0 0 0.0166666666667"/>
      <geometry>
        <cylinder length="0.0333333333333" radius="0.005"/>
      </geometry>
    </collision>
  </link>
  <gazebo reference="bpc_torso">
    <turnGravityOff>false</turnGravityOff>
    <genTexCoord>true</genTexCoord>
    <kp>100000000.0</kp>
    <kd>1000000.0</kd>
    <material>Gazebo/Black</material>
    <selfCollide>true</selfCollide>
  </gazebo>
  <joint name="bpd_base_joint" type="floating">
    <origin rpy="0 0 0" xyz="0.62 -0.168 0.4"/>
    <parent link="table_top_link"/>
    <child link="bpd_base"/>
  </joint>
  <link name="bpd_base">
    <inertial>
      <mass value="0.00666666666667"/>
      <!-- center of mass (com) is defined w.r.t. link local coordinate system -->
      <origin xyz="0 0 0.00833333333333"/>
      <inertia ixx="2.48070987654e-07" ixy="0" ixz="0" iyy="2.48070987654e-07" iyz="0" izz="1.875e-07"/>
    </inertial>
    <visual>
      <origin rpy="0 0 0" xyz="0 0 0.00833333333333"/>
      <geometry>
        <cylinder length="0.0166666666667" radius="0.0075"/>
      </geometry>
    </visual>
    <collision>
      <origin rpy="0 0 0" xyz="0 0 0.00833333333333"/>
      <geometry>
        <cylinder length="0.0166666666667" radius="0.0075"/>
      </geometry>
    </collision>
  </link>
  <gazebo reference="bpd_base">
    <turnGravityOff>false</turnGravityOff>
    <genTexCoord>true</genTexCoord>
    <kp>100000000.0</kp>
    <kd>1000000.0</kd>
    <material>Gazebo/Black</material>
    <selfCollide>true</selfCollide>
  </gazebo>
  <joint name="bpd_torso_joint" type="fixed">
    <origin rpy="0 0 0" xyz="0 0 0.0166666666667"/>
    <parent link="bpd_base"/>
    <child link="bpd_torso"/>
  </joint>
  <link name="bpd_torso">
    <inertial>
      <mass value="0.00333333333333"/>
      <!-- center of mass (com) is defined w.r.t. link local coordinate system -->
      <origin xyz="0 0 0.0166666666667"/>
      <inertia ixx="3.29475308642e-07" ixy="0" ixz="0" iyy="3.29475308642e-07" iyz="0" izz="4.16666666667e-08"/>
    </inertial>
    <visual>
      <origin rpy="0 0 0" xyz="0 0 0.0166666666667"/>
      <geometry>
        <cylinder length="0.0333333333333" radius="0.005"/>
      </geometry>
    </visual>
    <collision>
      <origin rpy="0 0 0" xyz="0 0 0.0166666666667"/>
      <geometry>
        <cylinder length="0.0333333333333" radius="0.005"/>
      </geometry>
    </collision>
  </link>
  <gazebo reference="bpd_torso">
    <turnGravityOff>false</turnGravityOff>
    <genTexCoord>true</genTexCoord>
    <kp>100000000.0</kp>
    <kd>1000000.0</kd>
    <material>Gazebo/Black</material>
    <selfCollide>true</selfCollide>
  </gazebo>
  <joint name="bpe_base_joint" type="floating">
    <origin rpy="0 0 0" xyz="0.62 -0.208 0.4"/>
    <parent link="table_top_link"/>
    <child link="bpe_base"/>
  </joint>
  <link name="bpe_base">
    <inertial>
      <mass value="0.00666666666667"/>
      <!-- center of mass (com) is defined w.r.t. link local coordinate system -->
      <origin xyz="0 0 0.00833333333333"/>
      <inertia ixx="2.48070987654e-07" ixy="0" ixz="0" iyy="2.48070987654e-07" iyz="0" izz="1.875e-07"/>
    </inertial>
    <visual>
      <origin rpy="0 0 0" xyz="0 0 0.00833333333333"/>
      <geometry>
        <cylinder length="0.0166666666667" radius="0.0075"/>
      </geometry>
    </visual>
    <collision>
      <origin rpy="0 0 0" xyz="0 0 0.00833333333333"/>
      <geometry>
        <cylinder length="0.0166666666667" radius="0.0075"/>
      </geometry>
    </collision>
  </link>
  <gazebo reference="bpe_base">
    <turnGravityOff>false</turnGravityOff>
    <genTexCoord>true</genTexCoord>
    <kp>100000000.0</kp>
    <kd>1000000.0</kd>
    <material>Gazebo/Black</material>
    <selfCollide>true</selfCollide>
  </gazebo>
  <joint name="bpe_torso_joint" type="fixed">
    <origin rpy="0 0 0" xyz="0 0 0.0166666666667"/>
    <parent link="bpe_base"/>
    <child link="bpe_torso"/>
  </joint>
  <link name="bpe_torso">
    <inertial>
      <mass value="0.00333333333333"/>
      <!-- center of mass (com) is defined w.r.t. link local coordinate system -->
      <origin xyz="0 0 0.0166666666667"/>
      <inertia ixx="3.29475308642e-07" ixy="0" ixz="0" iyy="3.29475308642e-07" iyz="0" izz="4.16666666667e-08"/>
    </inertial>
    <visual>
      <origin rpy="0 0 0" xyz="0 0 0.0166666666667"/>
      <geometry>
        <cylinder length="0.0333333333333" radius="0.005"/>
      </geometry>
    </visual>
    <collision>
      <origin rpy="0 0 0" xyz="0 0 0.0166666666667"/>
      <geometry>
        <cylinder length="0.0333333333333" radius="0.005"/>
      </geometry>
    </collision>
  </link>
  <gazebo reference="bpe_torso">
    <turnGravityOff>false</turnGravityOff>
    <genTexCoord>true</genTexCoord>
    <kp>100000000.0</kp>
    <kd>1000000.0</kd>
    <material>Gazebo/Black</material>
    <selfCollide>true</selfCollide>
  </gazebo>
  <joint name="bpf_base_joint" type="floating">
    <origin rpy="0 0 0" xyz="0.62 -0.248 0.4"/>
    <parent link="table_top_link"/>
    <child link="bpf_base"/>
  </joint>
  <link name="bpf_base">
    <inertial>
      <mass value="0.00666666666667"/>
      <!-- center of mass (com) is defined w.r.t. link local coordinate system -->
      <origin xyz="0 0 0.00833333333333"/>
      <inertia ixx="2.48070987654e-07" ixy="0" ixz="0" iyy="2.48070987654e-07" iyz="0" izz="1.875e-07"/>
    </inertial>
    <visual>
      <origin rpy="0 0 0" xyz="0 0 0.00833333333333"/>
      <geometry>
        <cylinder length="0.0166666666667" radius="0.0075"/>
      </geometry>
    </visual>
    <collision>
      <origin rpy="0 0 0" xyz="0 0 0.00833333333333"/>
      <geometry>
        <cylinder length="0.0166666666667" radius="0.0075"/>
      </geometry>
    </collision>
  </link>
  <gazebo reference="bpf_base">
    <turnGravityOff>false</turnGravityOff>
    <genTexCoord>true</genTexCoord>
    <kp>100000000.0</kp>
    <kd>1000000.0</kd>
    <material>Gazebo/Black</material>
    <selfCollide>true</selfCollide>
  </gazebo>
  <joint name="bpf_torso_joint" type="fixed">
    <origin rpy="0 0 0" xyz="0 0 0.0166666666667"/>
    <parent link="bpf_base"/>
    <child link="bpf_torso"/>
  </joint>
  <link name="bpf_torso">
    <inertial>
      <mass value="0.00333333333333"/>
      <!-- center of mass (com) is defined w.r.t. link local coordinate system -->
      <origin xyz="0 0 0.0166666666667"/>
      <inertia ixx="3.29475308642e-07" ixy="0" ixz="0" iyy="3.29475308642e-07" iyz="0" izz="4.16666666667e-08"/>
    </inertial>
    <visual>
      <origin rpy="0 0 0" xyz="0 0 0.0166666666667"/>
      <geometry>
        <cylinder length="0.0333333333333" radius="0.005"/>
      </geometry>
    </visual>
    <collision>
      <origin rpy="0 0 0" xyz="0 0 0.0166666666667"/>
      <geometry>
        <cylinder length="0.0333333333333" radius="0.005"/>
      </geometry>
    </collision>
  </link>
  <gazebo reference="bpf_torso">
    <turnGravityOff>false</turnGravityOff>
    <genTexCoord>true</genTexCoord>
    <kp>100000000.0</kp>
    <kd>1000000.0</kd>
    <material>Gazebo/Black</material>
    <selfCollide>true</selfCollide>
  </gazebo>
  <joint name="bpg_base_joint" type="floating">
    <origin rpy="0 0 0" xyz="0.62 -0.288 0.4"/>
    <parent link="table_top_link"/>
    <child link="bpg_base"/>
  </joint>
  <link name="bpg_base">
    <inertial>
      <mass value="0.00666666666667"/>
      <!-- center of mass (com) is defined w.r.t. link local coordinate system -->
      <origin xyz="0 0 0.00833333333333"/>
      <inertia ixx="2.48070987654e-07" ixy="0" ixz="0" iyy="2.48070987654e-07" iyz="0" izz="1.875e-07"/>
    </inertial>
    <visual>
      <origin rpy="0 0 0" xyz="0 0 0.00833333333333"/>
      <geometry>
        <cylinder length="0.0166666666667" radius="0.0075"/>
      </geometry>
    </visual>
    <collision>
      <origin rpy="0 0 0" xyz="0 0 0.00833333333333"/>
      <geometry>
        <cylinder length="0.0166666666667" radius="0.0075"/>
      </geometry>
    </collision>
  </link>
  <gazebo reference="bpg_base">
    <turnGravityOff>false</turnGravityOff>
    <genTexCoord>true</genTexCoord>
    <kp>100000000.0</kp>
    <kd>1000000.0</kd>
    <material>Gazebo/Black</material>
    <selfCollide>true</selfCollide>
  </gazebo>
  <joint name="bpg_torso_joint" type="fixed">
    <origin rpy="0 0 0" xyz="0 0 0.0166666666667"/>
    <parent link="bpg_base"/>
    <child link="bpg_torso"/>
  </joint>
  <link name="bpg_torso">
    <inertial>
      <mass value="0.00333333333333"/>
      <!-- center of mass (com) is defined w.r.t. link local coordinate system -->
      <origin xyz="0 0 0.0166666666667"/>
      <inertia ixx="3.29475308642e-07" ixy="0" ixz="0" iyy="3.29475308642e-07" iyz="0" izz="4.16666666667e-08"/>
    </inertial>
    <visual>
      <origin rpy="0 0 0" xyz="0 0 0.0166666666667"/>
      <geometry>
        <cylinder length="0.0333333333333" radius="0.005"/>
      </geometry>
    </visual>
    <collision>
      <origin rpy="0 0 0" xyz="0 0 0.0166666666667"/>
      <geometry>
        <cylinder length="0.0333333333333" radius="0.005"/>
      </geometry>
    </collision>
  </link>
  <gazebo reference="bpg_torso">
    <turnGravityOff>false</turnGravityOff>
    <genTexCoord>true</genTexCoord>
    <kp>100000000.0</kp>
    <kd>1000000.0</kd>
    <material>Gazebo/Black</material>
    <selfCollide>true</selfCollide>
  </gazebo>
  <joint name="bph_base_joint" type="floating">
    <origin rpy="0 0 0" xyz="0.62 -0.328 0.4"/>
    <parent link="table_top_link"/>
    <child link="bph_base"/>
  </joint>
  <link name="bph_base">
    <inertial>
      <mass value="0.00666666666667"/>
      <!-- center of mass (com) is defined w.r.t. link local coordinate system -->
      <origin xyz="0 0 0.00833333333333"/>
      <inertia ixx="2.48070987654e-07" ixy="0" ixz="0" iyy="2.48070987654e-07" iyz="0" izz="1.875e-07"/>
    </inertial>
    <visual>
      <origin rpy="0 0 0" xyz="0 0 0.00833333333333"/>
      <geometry>
        <cylinder length="0.0166666666667" radius="0.0075"/>
      </geometry>
    </visual>
    <collision>
      <origin rpy="0 0 0" xyz="0 0 0.00833333333333"/>
      <geometry>
        <cylinder length="0.0166666666667" radius="0.0075"/>
      </geometry>
    </collision>
  </link>
  <gazebo reference="bph_base">
    <turnGravityOff>false</turnGravityOff>
    <genTexCoord>true</genTexCoord>
    <kp>100000000.0</kp>
    <kd>1000000.0</kd>
    <material>Gazebo/Black</material>
    <selfCollide>true</selfCollide>
  </gazebo>
  <joint name="bph_torso_joint" type="fixed">
    <origin rpy="0 0 0" xyz="0 0 0.0166666666667"/>
    <parent link="bph_base"/>
    <child link="bph_torso"/>
  </joint>
  <link name="bph_torso">
    <inertial>
      <mass value="0.00333333333333"/>
      <!-- center of mass (com) is defined w.r.t. link local coordinate system -->
      <origin xyz="0 0 0.0166666666667"/>
      <inertia ixx="3.29475308642e-07" ixy="0" ixz="0" iyy="3.29475308642e-07" iyz="0" izz="4.16666666667e-08"/>
    </inertial>
    <visual>
      <origin rpy="0 0 0" xyz="0 0 0.0166666666667"/>
      <geometry>
        <cylinder length="0.0333333333333" radius="0.005"/>
      </geometry>
    </visual>
    <collision>
      <origin rpy="0 0 0" xyz="0 0 0.0166666666667"/>
      <geometry>
        <cylinder length="0.0333333333333" radius="0.005"/>
      </geometry>
    </collision>
  </link>
  <gazebo reference="bph_torso">
    <turnGravityOff>false</turnGravityOff>
    <genTexCoord>true</genTexCoord>
    <kp>100000000.0</kp>
    <kd>1000000.0</kd>
    <material>Gazebo/Black</material>
    <selfCollide>true</selfCollide>
  </gazebo>
</robot>

